<?xml version="1.0" ?>
<robot name="kinova_jaco">
    <link name="base_link">
        <inertial>
            <origin xyz="0 0 0" rpy="0 0 0" />
            <!-- Base link mass/interia never specified in KinovaJacoCfg.xml or KinovaJaco.xml?-->
            <mass value="4" />
            <inertia ixx="0.4" iyy="0.4" izz="0.4" ixy="0" ixz="0" iyz="0" />
        </inertial>
        <visual>
            <origin xyz="0 0 0" rpy="0 0 0" />
            <geometry>
                <mesh filename="kinova_jaco_graphics/base.obj" scale="0.001 0.001 0.001" />
            </geometry>
        </visual>
        <visual>
            <origin xyz="0 0 0.155" rpy="0 0 0" />
            <geometry>
                <mesh filename="kinova_jaco_graphics/ring-large.obj" scale = "0.001 0.001 0.001" />
            </geometry>
        </visual>
    </link>
    <link name="link0">
        <inertial>
            <origin xyz="0 0 0.06" rpy="0 -0 0" />
            <mass value="0.8" />
            <inertia ixx="0.1" iyy="0.1" izz="0.1" ixy="0" ixz="0" iyz="0" />
        </inertial>
        <visual>
            <origin xyz="0 0 0" rpy="-1.57079632679 0 -1.57079632679" />
            <geometry>
                <mesh filename="kinova_jaco_graphics/link0.obj" scale="0.001 0.001 0.001" />
            </geometry>
        </visual>
        <visual>
            <origin xyz="0 0 0.118" rpy="0 -1.57079632679 0" />
            <geometry>
                <mesh filename="kinova_jaco_graphics/ring-large.obj" scale = "0.001 0.001 0.001" />
            </geometry>
        </visual>
    </link>
    <link name="link1">
        <inertial>
            <origin xyz="0 0 0.2" rpy="0 -0 0" />
            <mass value="0.85" />
            <inertia ixx="0.1" iyy="0.1" izz="0.1" ixy="0" ixz="0" iyz="0" />
        </inertial>
        <visual>
            <origin xyz="0 0 0" rpy="3.14159265359 0 3.14159265359" />
            <geometry>
                <mesh filename="kinova_jaco_graphics/link1.obj" scale="0.001 0.001 0.001" />
            </geometry>
        </visual>
        <visual>
            <origin xyz="0 0 0.41" rpy="0 -1.57079632679 0" />
            <geometry>
                <mesh filename="kinova_jaco_graphics/ring-large.obj" scale = "0.001 0.001 0.001" />
            </geometry>
        </visual>
    </link>
    <link name="link2">
        <inertial>
            <origin xyz="0 0 0.2" rpy="0 -0 0" />
            <mass value="0.85" />
            <inertia ixx="0.1" iyy="0.1" izz="0.1" ixy="0" ixz="0" iyz="0" />
        </inertial>
        <visual>
            <origin xyz="0 0 0" rpy="-1.57079632679 0 0" />
            <geometry>
                <mesh filename="kinova_jaco_graphics/link2.obj" scale="0.001 0.001 0.001" />
            </geometry>
        </visual>
        <visual>
            <origin xyz="0.0098 0 0.2073" rpy="0 0 0" />
            <geometry>
                <mesh filename="kinova_jaco_graphics/ring-small.obj" scale = "0.001 0.001 0.001" />
            </geometry>
        </visual>
    </link>
    <link name="link3">
        <inertial>
            <origin xyz="0 0 0.1" rpy="0 0 0" />
            <mass value="0.85" />
            <inertia ixx="0.1" iyy="0.1" izz="0.1" ixy="0" ixz="0" iyz="0" />
        </inertial>
        <visual>
            <origin xyz="0 0 0.008" rpy="0 1.57079632679 0" />
            <geometry>
                <mesh filename="kinova_jaco_graphics/link3.obj" scale="0.001 0.001 0.001" />
            </geometry>
        </visual>
        <visual>
            <origin xyz="0 -0.03705 0.064172" rpy="0 0 0" />
            <geometry>
                <mesh filename="kinova_jaco_graphics/ring-small-rot45.obj" scale = "0.001 0.001 0.001" />
            </geometry>
        </visual>
    </link>
    <link name="link4">
        <inertial>
            <origin xyz="0 0 0.1" rpy="0 0 0" />
            <mass value="0.85" />
            <inertia ixx="0.1" iyy="0.1" izz="0.1" ixy="0" ixz="0" iyz="0" />
        </inertial>
        <visual>
            <origin xyz="0 0 0.008" rpy="0 1.57079632679 0" />
            <geometry>
                <mesh filename="kinova_jaco_graphics/link4.obj" scale="0.001 0.001 0.001" />
            </geometry>
        </visual>
        <visual>
            <origin xyz="0 -0.03705 0.064172" rpy="0 0 0" />
            <geometry>
                <mesh filename="kinova_jaco_graphics/ring-small-rot45.obj" scale = "0.001 0.001 0.001" />
            </geometry>
        </visual>
    </link>
    <link name="link5">
        <inertial>
            <origin xyz="0 0 0.1" rpy="0 0 0" />
            <mass value="0.727" />
            <inertia ixx="0.1" iyy="0.1" izz="0.1" ixy="0" ixz="0" iyz="0" />
        </inertial>
        <visual>
            <origin xyz="-0.0085 0.0075 0" rpy="1.57079632679 0 0" />
            <geometry>
                <mesh filename="kinova_jaco_graphics/link5-hand-base.obj" scale="0.001 0.001 0.001" />
            </geometry>
        </visual>
        <visual>
            <origin xyz="-0.0315 0 0.0825" rpy="-1.57079632679 0 0" />
            <geometry>
                <mesh filename="kinova_jaco_graphics/finger0-opposed.obj" scale = "0.001 0.001 0.001" />
            </geometry>
        </visual>
        <visual>
            <origin xyz="0.0315 0.025 0.0825" rpy="-1.57079632679 0 0" />
            <geometry>
                <mesh filename="kinova_jaco_graphics/finger1-clockwise-from-top.obj" scale = "0.001 0.001 0.001" />
            </geometry>
        </visual>
        <visual>
            <origin xyz="0.0315 -0.018 0.0825" rpy="-1.57079632679 0 0" />
            <geometry>
                <mesh filename="kinova_jaco_graphics/finger2-clockwise-from-top.obj" scale = "0.001 0.001 0.001" />
            </geometry>
        </visual>
        <collision>
            <origin xyz="-0.0085 0.0075 0" rpy="1.57079632679 0 0" />
            <geometry>
                <mesh filename="kinova_jaco_graphics/link5-hand-base.obj" scale="0.001 0.001 0.001" />
            </geometry>
        </collision>
    </link>

    <joint name="j0" type="revolute">
        <parent link="base_link" />
        <child link="link0" />
        <origin xyz="0.000000 0.000000 0.1575" rpy="0.000000 0.000000 0.000000" />
        <axis xyz="0 0 1" />
        <limit lower="-20" upper="20" effort="97.6" velocity="4" />
    </joint>
    <joint name="j1" type="revolute">
        <parent link="link0" />
        <child link="link1" />
        <origin xyz="0.000000 0.000000 0.118" rpy="0.000000 0.000000 0.000000" />
        <axis xyz="1 0 0" />
        <limit lower="-20" upper="20" effort="186.4" velocity="4" />
    </joint>
    <joint name="j2" type="revolute">
        <parent link="link1" />
        <child link="link2" />
        <origin xyz="0.000000 0.000000 0.41" rpy="0.000000 0.000000 0.000000" />
        <axis xyz="1 0 0" />
        <limit lower="-20" upper="20" effort="186.4" velocity="4" />
    </joint>
    <joint name="j3" type="revolute">
        <parent link="link2" />
        <child link="link3" />
        <origin xyz="0.0098 0.0 0.2073" rpy="0.000000 0.000000 0.000000" />
        <axis xyz="0 0 1" />
        <limit lower="-20" upper="20" effort="186.4" velocity="4" />
    </joint>
    <joint name="j4" type="revolute">
        <parent link="link3" />
        <child link="link4" />
        <origin xyz="0.0 -0.03705 0.064172" rpy="1.0471975512 0.000000 0.000000" />
        <axis xyz="0 0 1" />
        <limit lower="-20" upper="20" effort="186.4" velocity="4" />
    </joint>
    <joint name="j5" type="revolute">
        <parent link="link4" />
        <child link="link5" />
        <origin xyz="0.0 -0.03705 0.064172" rpy="1.0471975512 0.000000 0.000000" />
        <axis xyz="0 0 1" />
        <limit lower="-20" upper="20" effort="186.4" velocity="4" />
    </joint>
</robot>